Workbook

Sheet Pub Ratings
A1: Pub Name | B1: Location | C1: Price | D1: Date of Visit | E1: Alumni Present | F1: Taste | G1: Texture | H1: Stickage | I1: Head to Body Ratio | J1: Pub Character | K1: Overall Score | L1: Comments | M1: Woke? | N1: Overall Score (No Stickage)
A2: John Kehoe's | B2: South (City) | C2: 5.9 | D2: 44785 | E2: Adam, Cam, Fred, Martin, Saul | F2: 9.3 | G2: 9.4 | H2: 8.3 | I2: 9 | J2: 8.8 | K2: =AVERAGE(F2:J2) -> 8.96 | N2: =AVERAGE(F2,G2,I2,J2) -> 9.125
A3: The Long Hall | B3: South (City) | C3: 5.9 | D3: 44742 | E3: Cam, Fred, Kevin, Martin, Manus, Saul | F3: 8.3 | G3: 8.3 | H3: 7.8 | I3: 8.8 | J3: 8.8 | K3: =AVERAGE(F3:J3) -> 8.4 | N3: =AVERAGE(F3,G3,I3,J3) -> 8.55
A4: The Palace Bar | B4: South (City) | C4: 5.9 | D4: Unknown | E4: Alan, Cameron, Saul, Sophie | F4: 8.4 | G4: 8.3 | H4: 7.9 | I4: 8.9 | J4: 8 | K4: =AVERAGE(F4:J4) -> 8.3 | L4: "What an excellent pint. Delish creamy pint and a lovely pub atmosphere which I would like to grow old in. A nice dublin pub" - Sophie, "coffee" - Saul | N4: =AVERAGE(F4,G4,I4,J4) -> 8.4
A5: The Confession Box | B5: North (City) | C5: 5.5 | D5: 44765 | E5: Adam, Cam, Martin, Saul | F5: 8.8 | G5: 9.1 | H5: 7.4 | I5: 7.8 | J5: 8.2 | K5: =AVERAGE(F5:J5) -> 8.26 | N5: =AVERAGE(F5,G5,I5,J5) -> 8.475
A6: The Stag's Head | B6: South (City) | C6: 5.9 | D6: 44742 | E6: Cam, Fred, Kevin, Martin, Saul | F6: 8.7 | G6: 8.4 | H6: 7.6 | I6: 7.7 | J6: 8.6 | K6: =AVERAGE(F6:J6) -> 8.2 | N6: =AVERAGE(F6,G6,I6,J6) -> 8.35
A7: Chaplins | B7: South (City) | C7: 5.5 | D7: 44735 | E7: Alan, Cam, Martin, Saul | F7: 8 | G7: 7.9 | H7: 8.6 | I7: 8.1 | J7: 8 | K7: =AVERAGE(F7:J7) -> 8.12 | L7: Smooth yet slightly watery towards the end. A lovely sweet smell of coffee, a tad cold but excellent domage and a nice firm head. The stickage did wonders for the score of this pint and taste brought it up big time. Chaplin's is a lovely intimate vibe perfect for a few quiet ones with the lads in the evening and a few more lively pints at night. Staff are always friendly and you can tell the owners care about the place. | N7: =AVERAGE(F7,G7,I7,J7) -> 8
A8: Bowe's | B8: South (City) | C8: 5.7 | D8: Unknown | E8: Adam, Cameron, Matthew, Saul, Sophie | F8: 8.4 | G8: 8.3 | H8: 8 | I8: 8.1 | J8: 7.8 | K8: =AVERAGE(F8:J8) -> 8.12 | L8: "nice tasty Guinness" - Matthew | N8: =AVERAGE(F8,G8,I8,J8) -> 8.15
A9: Mooney's | B9: North (City) | C9: 5.7 | D9: 44765 | E9: Adam, Cam, Martin, Saul | F9: 8.2 | G9: 7.9 | H9: 8.8 | I9: 7.8 | J9: 7.8 | K9: =AVERAGE(F9:J9) -> 8.1 | N9: =AVERAGE(F9,G9,I9,J9) -> 7.925
A10: Uncle Tom's Cabin | B10: South | C10: 5.5 | D10: Unknown | E10: Manus, Mark, Martin, Matthew, Saul | F10: 8 | G10: 8 | H10: 7.7 | I10: 8.8 | J10: 8 | K10: =AVERAGE(F10:J10) -> 8.1 | L10: "from the looks of it every man here had the name Mick" - Martin, "a cabin of dreams" - Matthew, "funny place" - Manus | N10: =AVERAGE(F10,G10,I10,J10) -> 8.2
A11: The Manhattan (Raheny) | B11: North | C11: 5.9 | D11: 44876 | E11: Cam, Mark, Martin, Podge | F11: 8.5 | G11: 8 | H11: 7.8 | I11: 8 | J11: 8.1 | K11: =AVERAGE(F11:J11) -> 8.08 | N11: =AVERAGE(F11,G11,I11,J11) -> 8.15
A12: Annesley House | B12: North | C12: 4.8 | D12: 44894 | E12: Cam, Martin, Matthew, Podge, Saul, Sophie | F12: 8.6 | G12: 8.2 | H12: 7.7 | I12: 8.2 | J12: 7.6 | K12: =AVERAGE(F12:J12) -> 8.06 | L12: "A truly Irish House. Annesley House. Crown Moldings. Wall Molding. Bar man drinking. Old man sinking. A happy place. A cheap pint. A great find." - Martin | N12: =AVERAGE(F12,G12,I12,J12) -> 8.15
A13: Paddy Kearney's | B13: South (City) | C13: Unknown | D13: 45634 | E13: Alan, Kevin, Martin, Saul | F13: 8.2 | G13: 7.9 | H13: 8.4 | I13: 7.4 | J13: 8.4 | K13: =AVERAGE(F13:J13) -> 8.06 | L13: "Ooh Ah Up The" - Martin, "RA" - Alan | M13: No | N13: =AVERAGE(F13,G13,I13,J13) -> 7.975
A14: Patrick Carthy & Sons | B14: North | C14: 5.4 | D14: 44837 | E14: Alan, Martin, Manus, Saul | F14: 8.6 | G14: 8.5 | H14: 8.9 | I14: 8 | J14: 6.1 | K14: =AVERAGE(F14:J14) -> 8.02 | N14: =AVERAGE(F14,G14,I14,J14) -> 7.8
A15: The Dame Tavern | B15: South (City) | C15: 5.8 | D15: 44742 | E15: Cam, Kevin, Martin, Manus, Saul | F15: 7.5 | G15: 7.8 | H15: 7.5 | I15: 8.1 | J15: 9.1 | K15: =AVERAGE(F15:J15) -> 8 | N15: =AVERAGE(F15,G15,I15,J15) -> 8.125
A16: Millmount House | B16: North | C16: 5 | D16: 44822 | E16: Alan, Matthew, Podge, Saul | F16: 8.3 | G16: 8.1 | H16: 8.5 | I16: 7.7 | J16: 7.4 | K16: =AVERAGE(F16:J16) -> 8 | N16: =AVERAGE(F16,G16,I16,J16) -> 7.875
A17: The Glimmerman | B17: North | C17: 5.5 | D17: 44783 | E17: Martin, Matthew, Podge, Saul | F17: 7.5 | G17: 7.7 | H17: 7.9 | I17: 7.9 | J17: 8.7 | K17: =AVERAGE(F17:J17) -> 7.94 | N17: =AVERAGE(F17,G17,I17,J17) -> 7.95
A18: Walsh's | B18: North | C18: 5.6 | D18: 44783 | E18: Martin, Matthew, Podge, Saul | F18: 8.5 | G18: 7.8 | H18: 7.1 | I18: 8.4 | J18: 7.9 | K18: =AVERAGE(F18:J18) -> 7.94 | N18: =AVERAGE(F18,G18,I18,J18) -> 8.15
A19: Glynns | B19: North (City) | C19: 6.25 | D19: 45913 | E19: Adam, Cam, Kevin, Mark, Martin, Saul | F19: 7.9 | G19: 7.7 | H19: 7.3 | I19: 7.7 | J19: 9 | K19: =AVERAGE(F19:J19) -> 7.92 | L19: "the most dublin pub of all time" - Saul, "the strippers have arrived" - Cam, "chlorine stench. Sour cranberries" - Martin, "the locals were so sweet" - Adam | M19: No | N19: =AVERAGE(F19,G19,I19,J19) -> 8.075
A20: O'Loughlin's | B20: South | C20: 5 | D20: 44849 | E20: Mark, Martin, Matthew, Podge, Saul, Sophie | F20: 7.7 | G20: 7.9 | H20: 8.8 | I20: 7.6 | J20: 7.5 | K20: =AVERAGE(F20:J20) -> 7.9 | N20: =AVERAGE(F20,G20,I20,J20) -> 7.675
A21: Doyle's | B21: South (City) | C21: 5.9 | D21: 44755 | E21: Adam, Cam, Fred, Mark, Martin, Saul | F21: 7.7 | G21: 7.7 | H21: 7.6 | I21: 7.9 | J21: 8.4 | K21: =AVERAGE(F21:J21) -> 7.86 | N21: =AVERAGE(F21,G21,I21,J21) -> 7.925
A22: Harry Byrne's | B22: North | C22: 5.7 | D22: 44826 | E22: Cam, Matthew, Podge, Saul, Sophie | F22: 7.9 | G22: 7.6 | H22: 7.6 | I22: 8.2 | J22: 8 | K22: =AVERAGE(F22:J22) -> 7.86 | N22: =AVERAGE(F22,G22,I22,J22) -> 7.925
A23: Kitty Kiernan's | B23: North | C23: 5.3 | D23: 44854 | E23: Adam, Cam, Mark, Martin, Podge, Saul | F23: 8.4 | G23: 7.9 | H23: 6.8 | I23: 8.4 | J23: 7.7 | K23: =AVERAGE(F23:J23) -> 7.84 | N23: =AVERAGE(F23,G23,I23,J23) -> 8.1
A24: The Beachcomber | B24: North | C24: 5.6 | D24: 44854 | E24: Cam, Mark, Martin, Saul | F24: 7.9 | G24: 7 | H24: 8.6 | I24: 8.3 | J24: 7.3 | K24: =AVERAGE(F24:J24) -> 7.82 | N24: =AVERAGE(F24,G24,I24,J24) -> 7.625
A25: McNeill's (Howth) | B25: North | C25: 5.5 | D25: Unknown | E25: Adam, Martin, Matthew, Saul | F25: 7.9 | G25: 7.9 | H25: 7.8 | I25: 8.1 | J25: 7.4 | K25: =AVERAGE(F25:J25) -> 7.82 | L25: "Alan is an idiot" - Matthew, "Got Sharked" - Martin | N25: =AVERAGE(F25,G25,I25,J25) -> 7.825
A26: Mary's | B26: South (City) | C26: 5.9 | D26: 44794 | E26: Adam, Fred, Martin, Saul | F26: 8.4 | G26: 7.8 | H26: 7.2 | I26: 7 | J26: 8.7 | K26: =AVERAGE(F26:J26) -> 7.82 | N26: =AVERAGE(F26,G26,I26,J26) -> 7.975
A27: The Flowing Tide | B27: North (City) | C27: 5.8 | D27: 44889 | E27: Adam, Cam, Mark, Martin | F27: 7.9 | G27: 7.8 | H27: 7.5 | I27: 7.7 | J27: 8.2 | K27: =AVERAGE(F27:J27) -> 7.82 | N27: =AVERAGE(F27,G27,I27,J27) -> 7.9
A28: Grogan's | B28: South (City) | C28: 5.95 | D28: 44878 | E28: Adam, Martin, Podge, Saul | F28: 8.1 | G28: 8.1 | H28: 7.6 | I28: 7.6 | J28: 7.6 | K28: =AVERAGE(F28:J28) -> 7.8 | N28: =AVERAGE(F28,G28,I28,J28) -> 7.85
A29: Smyths | B29: North | C29: 5.75 | D29: 45270 | E29: Alan, Fred, Kevin, Martin, Matthew, Padraig, Saul | F29: 7.5 | G29: 7.8 | H29: 7.4 | I29: 7.7 | J29: 8.5 | K29: =AVERAGE(F29:J29) -> 7.78 | L29: "Is that your jacket 🙄" - Martin, "Hand dryer not branded but powerful" - Padraig | N29: =AVERAGE(F29,G29,I29,J29) -> 7.875
A30: Kavanagh's (Clontarf) | B30: North | C30: 5.5 | D30: 44907 | E30: Cam, Martin, Matthew, Podge, Saul | F30: 7.9 | G30: 7.7 | H30: 7.7 | I30: 7.8 | J30: 7.8 | K30: =AVERAGE(F30:J30) -> 7.78 | L30: "that'll do" - Martin | N30: =AVERAGE(F30,G30,I30,J30) -> 7.8
A31: The Boar's Head | B31: North (City) | C31: 6.6 | D31: 45219 | E31: Martin, Matthew, Saul, Sophie | F31: 8 | G31: 7.4 | H31: 7.5 | I31: 8.1 | J31: 7.8 | K31: =AVERAGE(F31:J31) -> 7.76 | L31: "Capel st giving me that Asian flush (I did big poo after noodles)" - Martin, "The tourist table is the best spot in this place" - Sophie | N31: =AVERAGE(F31,G31,I31,J31) -> 7.825
A32: Horse and Hound | B32: North | C32: 5.9 | D32: 45270 | E32: Alan, Fred, Kevin, Martin, Matthew, Padraig, Saul | F32: 7.8 | G32: 7.4 | H32: 7.4 | I32: 8 | J32: 8.2 | K32: =AVERAGE(F32:J32) -> 7.76 | L32: "They got KEVIN O’SULLIVAN to play. The KEVIN O’SULLIVAN. Yeah, that KEVIN O’SULLIVAN, the one they you’re thinking about. Famous singer KEVIN O’SULLIVAN. Shedding on the electric, KEVIN O’SULLIVAN. Not Adam O’Sullivan. KEVIN O’SULLIVAN" - Martin, "atc cooking styll" - Padraig | N32: =AVERAGE(F32,G32,I32,J32) -> 7.85
A33: The Old Punch Bowl | B33: South | C33: 6.5 | D33: 45326 | E33: Adam, Fred, Kevin, Mark, Martin, Padraig, Saul, Sophie | F33: 7.6 | G33: 7.2 | H33: 7.7 | I33: 8 | J33: 8.3 | K33: =AVERAGE(F33:J33) -> 7.76 | L33: "Good decor and hagrid core" - Padraig | N33: =AVERAGE(F33,G33,I33,J33) -> 7.775
A34: The Bridge Tavern | B34: North | C34: 4.9 | D34: Unknown | E34: Alan, Cameron, Mark, Martin, Saul | F34: 7.5 | G34: 7.1 | H34: 7.3 | I34: 8.6 | J34: 8.2 | K34: =AVERAGE(F34:J34) -> 7.74 | L34: "u-n-i t-e-d United are the team for me" - Saul, "call an ambulance but not for me" - Martin | N34: =AVERAGE(F34,G34,I34,J34) -> 7.85
A35: Cassidy's (Westmoreland) | B35: South (City) | C35: 5.8 | D35: 44755 | E35: Adam, Fred, Martin, Saul | F35: 7.1 | G35: 7.7 | H35: 7.9 | I35: 7.6 | J35: 8.3 | K35: =AVERAGE(F35:J35) -> 7.72 | N35: =AVERAGE(F35,G35,I35,J35) -> 7.675
A36: Dudley's | B36: South (City) | C36: 6.6 | D36: 45618 | E36: Cam, Fred, Kevin, Martin, Ruairí, Saul | F36: 7.8 | G36: 7.5 | H36: 7.4 | I36: 7.6 | J36: 8.3 | K36: =AVERAGE(F36:J36) -> 7.72 | L36: "Walking stick theory wouldn't fly somewhere this woke" - Martin. Note: Ruairí failed to rate H2B and Kevin failed to rate stickage | M36: Half woke | N36: =AVERAGE(F36,G36,I36,J36) -> 7.8
A37: Mulligan's | B37: South (City) | C37: 5.9 | D37: 44735 | E37: Alan, Cam, Martin, Saul | F37: 8.4 | G37: 8.4 | H37: 6.3 | I37: 7.2 | J37: 8.3 | K37: =AVERAGE(F37:J37) -> 7.72 | L37: A regular haunt of mine, I know the barmen well and its been a Farrelly pub for generations. The atmosphere is always fantastic, just a classic of Dublin. The pint was smooth, creamy and well balanced. Nice temperature and deliciously malty for whatever reason, however it wasn't quite as good as expected, I've had better in there. The stickage was very poor and the head to body ratio wasn't up to the standards we've come to expect from Mulligan's | N37: =AVERAGE(F37,G37,I37,J37) -> 8.075
A38: Ukiyo** | B38: South (City) | C38: 6 | D38: 44830 | E38: Martin, Manus, Matthew, Sophie | F38: 8.4 | G38: 7.9 | H38: 6.8 | I38: 8 | J38: 7.5 | K38: =AVERAGE(F38:J38) -> 7.72 | N38: =AVERAGE(F38,G38,I38,J38) -> 7.95
A39: Meagher's (Fairview) | B39: North | C39: Unknown | D39: Unknown | E39: Cameron, Mark, Padraig, Saul | F39: 7.3 | G39: 7.3 | H39: 8 | I39: 7.9 | J39: 8.1 | K39: =AVERAGE(F39:J39) -> 7.72 | L39: "queit" - Saul, "Dómhnál is a crack head" - Padraig | N39: =AVERAGE(F39,G39,I39,J39) -> 7.65
A40: Harkin's | B40: South (City) | C40: 5.4 | D40: Unknown | E40: Mark, Martin, Matthew, Saul | F40: 7.9 | G40: 7.7 | H40: 7 | I40: 8.1 | J40: 7.9 | K40: =AVERAGE(F40:J40) -> 7.72 | L40: Possibly invalid rating as Matthew failed to rate stickage. "cosy vibe, feels like a Northside job. Smells like delicious" - Martin, "lovely stuff" - Saul, "oops forgot to send" - Matthew | N40: =AVERAGE(F40,G40,I40,J40) -> 7.9
...

Sheet Alumni Stats
A1: Alumni | B1: Pubs Visited | C1: Average Pub Score | D1: Attendance Record | E1: Money Invested
A2: Saul | B2: =COUNTIF('Pub Ratings'!E$2:E$209, "*Saul*") -> 181 | C2: =AVERAGEIF('Pub Ratings'!E:E, "*Saul*", 'Pub Ratings'!K:K) -> 7.1550276 | D2: =B2/E25 -> 0.80803571 | E2: =SUMIF('Pub Ratings'!E:E, "*Saul*", 'Pub Ratings'!C:C) -> 983.25
A3: Martin | B3: =COUNTIF('Pub Ratings'!E$2:E$209, "*Martin*") -> 136 | C3: =AVERAGEIF('Pub Ratings'!E:E, "*Martin*", 'Pub Ratings'!K:K) -> 7.1998529 | D3: =B3/E25 -> 0.60714286 | E3: =SUMIF('Pub Ratings'!E:E, "*Martin*", 'Pub Ratings'!C:C) -> 765.55
A4: Cam | B4: =COUNTIF('Pub Ratings'!E$2:E$209, "*Cam*") -> 113 | C4: =AVERAGEIF('Pub Ratings'!E:E, "*Cam*", 'Pub Ratings'!K:K) -> 7.1357522 | D4: =B4/E25 -> 0.50446429 | E4: =SUMIF('Pub Ratings'!E:E, "*Cam*", 'Pub Ratings'!C:C) -> 633.75
A5: Kevin | B5: =COUNTIF('Pub Ratings'!E$2:E$209, "*Kevin*") -> 96 | C5: =AVERAGEIF('Pub Ratings'!E:E, "*Kevin*", 'Pub Ratings'!K:K) -> 7.0129167 | D5: =B5/E25 -> 0.42857143 | E5: =SUMIF('Pub Ratings'!E:E, "*Kevin*", 'Pub Ratings'!C:C) -> 565.6
A6: Matthew | B6: =COUNTIF('Pub Ratings'!E:E, "*Matthew*") -> 87 | C6: =AVERAGEIF('Pub Ratings'!E:E, "*Matthew*", 'Pub Ratings'!K:K) -> 7.1908046 | D6: =B6/E25 -> 0.38839286 | E6: =SUMIF('Pub Ratings'!E:E, "*Matthew*", 'Pub Ratings'!C:C) -> 494.95
A7: Adam | B7: =COUNTIF('Pub Ratings'!E$2:E$209, "*Adam*") -> 81 | C7: =AVERAGEIF('Pub Ratings'!E:E, "*Adam*", 'Pub Ratings'!K:K) -> 7.0577778 | D7: =B7/E25 -> 0.36160714 | E7: =SUMIF('Pub Ratings'!E:E, "*Adam*", 'Pub Ratings'!C:C) -> 447.1
A8: Fred | B8: =COUNTIF('Pub Ratings'!E$2:E$209, "*Fred*") -> 76 | C8: =AVERAGEIF('Pub Ratings'!E:E, "*Fred*", 'Pub Ratings'!K:K) -> 7.07 | D8: =B8/E25 -> 0.33928571 | E8: =SUMIF('Pub Ratings'!E:E, "*Fred*", 'Pub Ratings'!C:C) -> 424.45
A9: Mark | B9: =COUNTIF('Pub Ratings'!E$2:E$209, "*Mark*") -> 60 | C9: =AVERAGEIF('Pub Ratings'!E:E, "*Mark*", 'Pub Ratings'!K:K) -> 7.1996667 | D9: =B9/E25 -> 0.26785714 | E9: =SUMIF('Pub Ratings'!E:E, "*Mark*", 'Pub Ratings'!C:C) -> 318.4
A10: Sophie | B10: =COUNTIF('Pub Ratings'!E$2:E$209, "*Sophie*") -> 58 | C10: =AVERAGEIF('Pub Ratings'!E:E, "*Sophie*", 'Pub Ratings'!K:K) -> 7.0796552 | D10: =B10/E25 -> 0.25892857 | E10: =SUMIF('Pub Ratings'!E:E, "*Sophie*", 'Pub Ratings'!C:C) -> 332.3
A11: Alan | B11: =COUNTIF('Pub Ratings'!E$2:E$209, "*Alan*") -> 40 | C11: =AVERAGEIF('Pub Ratings'!E:E, "*Alan*", 'Pub Ratings'!K:K) -> 7.183 | D11: =B11/E25 -> 0.17857143 | E11: =SUMIF('Pub Ratings'!E:E, "*Alan*", 'Pub Ratings'!C:C) -> 220.05
A12: Podge | B12: =COUNTIF('Pub Ratings'!E$2:E$209, "*Podge*") -> 30 | C12: =AVERAGEIF('Pub Ratings'!E:E, "*Podge*", 'Pub Ratings'!K:K) -> 7.3493333 | D12: =B12/E25 -> 0.13392857 | E12: =SUMIF('Pub Ratings'!E:E, "*Podge*", 'Pub Ratings'!C:C) -> 167.25
A13: Padraig | B13: =COUNTIF('Pub Ratings'!E$2:E$209, "*Padraig*") -> 30 | C13: =AVERAGEIF('Pub Ratings'!E:E, "*Padraig*", 'Pub Ratings'!K:K) -> 7.0193333 | D13: =B13/E25 -> 0.13392857 | E13: =SUMIF('Pub Ratings'!E:E, "*Padraig*", 'Pub Ratings'!C:C) -> 138.3
A14: Manus | B14: =COUNTIF('Pub Ratings'!E$2:E$209, "*Manus*") -> 18 | C14: =AVERAGEIF('Pub Ratings'!E:E, "*Manus*", 'Pub Ratings'!K:K) -> 7.3255556 | D14: =B14/E25 -> 0.080357143 | E14: =SUMIF('Pub Ratings'!E:E, "*Manus*", 'Pub Ratings'!C:C) -> 105.75
A15: Sadhbh N | B15: =COUNTIF('Pub Ratings'!E:E, "*Sadhbh N*") -> 16 | C15: =AVERAGEIF('Pub Ratings'!E:E, "*Sadhbh N*", 'Pub Ratings'!K:K) -> 7.05875 | D15: =B15/E25 -> 0.071428571 | E15: =SUMIF('Pub Ratings'!E:E, "*Sadhbh N*", 'Pub Ratings'!C:C) -> 101.45
A16: Sadhbh D | B16: =COUNTIF('Pub Ratings'!E$2:E$209, "*Sadhbh D*") -> 6 | C16: =AVERAGEIF('Pub Ratings'!E:E, "*Sadhbh D*", 'Pub Ratings'!K:K) -> 6.7933333 | D16: =B16/E25 -> 0.026785714 | E16: =SUMIF('Pub Ratings'!E:E, "*Sadhbh D*", 'Pub Ratings'!C:C) -> 39.15
A17: Rachael | B17: =COUNTIF('Pub Ratings'!E$2:E$209, "*Rachael*") -> 4 | C17: =AVERAGEIF('Pub Ratings'!E:E, "*Rachael*", 'Pub Ratings'!K:K) -> 6.95 | D17: =B17/E25 -> 0.017857143 | E17: =SUMIF('Pub Ratings'!E:E, "*Rachael*", 'Pub Ratings'!C:C) -> 25.2
A18: Rebecca | B18: =COUNTIF('Pub Ratings'!E$2:E$209, "*Rebecca*") -> 3 | C18: =AVERAGEIF('Pub Ratings'!E:E, "*Rebecca*", 'Pub Ratings'!K:K) -> 6.3133333 | D18: =B18/E25 -> 0.013392857 | E18: =SUMIF('Pub Ratings'!E:E, "*Rebecca*", 'Pub Ratings'!C:C) -> 19.1
A19: Thomas | B19: =COUNTIF('Pub Ratings'!E$2:E$209, "*Thomas*") -> 1 | C19: =AVERAGEIF('Pub Ratings'!E:E, "*Thomas*", 'Pub Ratings'!K:K) -> 7.04 | D19: =B19/E25 -> 0.0044642857 | E19: =SUMIF('Pub Ratings'!E:E, "*Thomas*", 'Pub Ratings'!C:C) -> 6.9
D21: Total Money Invested: | E21: =SUM(E1:E19) -> 5788.5
D23: Total Pints Rated: | E23: =sum(B2:B19) -> 1036
D25: Total Pubs Rated: | E25: 224
D27: Pubs of total 632 rated: | E27: =224/632 -> 0.35443038

Sheet STATS
B2: Taste vs Overall Ranking Correlation | C2: Texture vs Overall Ranking Correlation | D2: Stickage vs Overall Ranking Correlation | E2: H2B vs Overall Ranking Correlation | F2: Pub Quality vs Overall Ranking Correlation
B3: =CORREL('Pub Ratings'!F:F,'Pub Ratings'!K:K) -> 0.8727088 | C3: =CORREL('Pub Ratings'!G:G,'Pub Ratings'!K:K) -> 0.83562242 | D3: =CORREL('Pub Ratings'!H:H,'Pub Ratings'!K:K) -> 0.74397364 | E3: =CORREL('Pub Ratings'!I:I,'Pub Ratings'!K:K) -> 0.74602035 | F3: =CORREL('Pub Ratings'!J:J,'Pub Ratings'!K:K) -> 0.69537273
B6: Date | C6: Monthly Average Pint Price
B7: 44713 | C7: =AVERAGEIFS('Pub Ratings'!C:C, 'Pub Ratings'!D:D, ">="&B7, 'Pub Ratings'!D:D, "<"&B8) -> 5.5833333
B8: =EOMONTH(B7, 0) + 1 -> 44743 | C8: =AVERAGEIFS('Pub Ratings'!C:C, 'Pub Ratings'!D:D, ">="&B8, 'Pub Ratings'!D:D, "<"&B9) -> 5.7454545
B9: =EOMONTH(B8, 0) + 1 -> 44774 | C9: =AVERAGEIFS('Pub Ratings'!C:C, 'Pub Ratings'!D:D, ">="&B9, 'Pub Ratings'!D:D, "<"&B10) -> 5.6833333
B10: =EOMONTH(B9, 0) + 1 -> 44805 | C10: =AVERAGEIFS('Pub Ratings'!C:C, 'Pub Ratings'!D:D, ">="&B10, 'Pub Ratings'!D:D, "<"&B11) -> 5.6428571
B11: =EOMONTH(B10, 0) + 1 -> 44835 | C11: =AVERAGEIFS('Pub Ratings'!C:C, 'Pub Ratings'!D:D, ">="&B11, 'Pub Ratings'!D:D, "<"&B12) -> 5.6071429
B12: =EOMONTH(B11, 0) + 1 -> 44866 | C12: =AVERAGEIFS('Pub Ratings'!C:C, 'Pub Ratings'!D:D, ">="&B12, 'Pub Ratings'!D:D, "<"&B13) -> 5.6888889
B13: =EOMONTH(B12, 0) + 1 -> 44896 | C13: =AVERAGEIFS('Pub Ratings'!C:C, 'Pub Ratings'!D:D, ">="&B13, 'Pub Ratings'!D:D, "<"&B14) -> 5.5857143
B14: =EOMONTH(B13, 0) + 1 -> 44927 | C14: =AVERAGEIFS('Pub Ratings'!C:C, 'Pub Ratings'!D:D, ">="&B13, 'Pub Ratings'!D:D, "<"&B14) -> 5.5857143
B15: =EOMONTH(B14, 0) + 1 -> 44958 | C15: =AVERAGEIFS('Pub Ratings'!C:C, 'Pub Ratings'!D:D, ">="&B13, 'Pub Ratings'!D:D, "<"&B14) -> 5.5857143
B16: =EOMONTH(B15, 0) + 1 -> 44986 | C16: =AVERAGEIFS('Pub Ratings'!C:C, 'Pub Ratings'!D:D, ">="&B13, 'Pub Ratings'!D:D, "<"&B14) -> 5.5857143
B17: =EOMONTH(B16, 0) + 1 -> 45017 | C17: =AVERAGEIFS('Pub Ratings'!C:C, 'Pub Ratings'!D:D, ">="&B13, 'Pub Ratings'!D:D, "<"&B14) -> 5.5857143
B18: =EOMONTH(B17, 0) + 1 -> 45047 | C18: =AVERAGEIFS('Pub Ratings'!C:C, 'Pub Ratings'!D:D, ">="&B18, 'Pub Ratings'!D:D, "<"&B19) -> 6.2
B19: =EOMONTH(B18, 0) + 1 -> 45078 | C19: =AVERAGEIFS('Pub Ratings'!C:C, 'Pub Ratings'!D:D, ">="&B18, 'Pub Ratings'!D:D, "<"&B19) -> 6.2
B20: =EOMONTH(B19, 0) + 1 -> 45108 | C20: =AVERAGEIFS('Pub Ratings'!C:C, 'Pub Ratings'!D:D, ">="&B20, 'Pub Ratings'!D:D, "<"&B21) -> 6.5
B21: =EOMONTH(B20, 0) + 1 -> 45139 | C21: =AVERAGEIFS('Pub Ratings'!C:C, 'Pub Ratings'!D:D, ">="&B20, 'Pub Ratings'!D:D, "<"&B21) -> 6.5
B22: =EOMONTH(B21, 0) + 1 -> 45170 | C22: =AVERAGEIFS('Pub Ratings'!C:C, 'Pub Ratings'!D:D, ">="&B20, 'Pub Ratings'!D:D, "<"&B21) -> 6.5
B23: =EOMONTH(B22, 0) + 1 -> 45200 | C23: =AVERAGEIFS('Pub Ratings'!C:C, 'Pub Ratings'!D:D, ">="&B20, 'Pub Ratings'!D:D, "<"&B21) -> 6.5
B24: =EOMONTH(B23, 0) + 1 -> 45231 | C24: =AVERAGEIFS('Pub Ratings'!C:C, 'Pub Ratings'!D:D, ">="&B24, 'Pub Ratings'!D:D, "<"&B25) -> 5.875
B25: =EOMONTH(B24, 0) + 1 -> 45261 | C25: =AVERAGEIFS('Pub Ratings'!C:C, 'Pub Ratings'!D:D, ">="&B25, 'Pub Ratings'!D:D, "<"&B26) -> 6.2875
B26: =EOMONTH(B25, 0) + 1 -> 45292 | C26: =AVERAGEIFS('Pub Ratings'!C:C, 'Pub Ratings'!D:D, ">="&B26, 'Pub Ratings'!D:D, "<"&B27) -> 6.2
B27: =EOMONTH(B26, 0) + 1 -> 45323 | C27: =AVERAGEIFS('Pub Ratings'!C:C, 'Pub Ratings'!D:D, ">="&B27, 'Pub Ratings'!D:D, "<"&B28) -> 6.33
B28: =EOMONTH(B27, 0) + 1 -> 45352 | C28: =AVERAGEIFS('Pub Ratings'!C:C, 'Pub Ratings'!D:D, ">="&B28, 'Pub Ratings'!D:D, "<"&B29) -> 5.9
B29: =EOMONTH(B28, 0) + 1 -> 45383 | C29: =AVERAGEIFS('Pub Ratings'!C:C, 'Pub Ratings'!D:D, ">="&B28, 'Pub Ratings'!D:D, "<"&B29) -> 5.9
B30: =EOMONTH(B29, 0) + 1 -> 45413 | C30: =AVERAGEIFS('Pub Ratings'!C:C, 'Pub Ratings'!D:D, ">="&B30, 'Pub Ratings'!D:D, "<"&B31) -> 6.5
B31: =EOMONTH(B30, 0) + 1 -> 45444 | C31: =AVERAGEIFS('Pub Ratings'!C:C, 'Pub Ratings'!D:D, ">="&B30, 'Pub Ratings'!D:D, "<"&B31) -> 6.5
B32: =EOMONTH(B31, 0) + 1 -> 45474 | C32: =AVERAGEIFS('Pub Ratings'!C:C, 'Pub Ratings'!D:D, ">="&B32, 'Pub Ratings'!D:D, "<"&B33) -> 6.45
B33: =EOMONTH(B32, 0) + 1 -> 45505 | C33: =AVERAGEIFS('Pub Ratings'!C:C, 'Pub Ratings'!D:D, ">="&B33, 'Pub Ratings'!D:D, "<"&B34) -> 6.2
B34: =EOMONTH(B33, 0) + 1 -> 45536 | C34: =AVERAGEIFS('Pub Ratings'!C:C, 'Pub Ratings'!D:D, ">="&B34, 'Pub Ratings'!D:D, "<"&B35) -> 6.95
B35: =EOMONTH(B34, 0) + 1 -> 45566 | C35: =AVERAGEIFS('Pub Ratings'!C:C, 'Pub Ratings'!D:D, ">="&B35, 'Pub Ratings'!D:D, "<"&B36) -> 6.0333333
B36: =EOMONTH(B35, 0) + 1 -> 45597 | C36: =AVERAGEIFS('Pub Ratings'!C:C, 'Pub Ratings'!D:D, ">="&B36, 'Pub Ratings'!D:D, "<"&B37) -> 6.2583333
B37: =EOMONTH(B36, 0) + 1 -> 45627 | C37: =AVERAGEIFS('Pub Ratings'!C:C, 'Pub Ratings'!D:D, ">="&B37, 'Pub Ratings'!D:D, "<"&B38) -> 6.6772727
B38: =EOMONTH(B37, 0) + 1 -> 45658 | C38: =AVERAGEIFS('Pub Ratings'!C:C, 'Pub Ratings'!D:D, ">="&B38, 'Pub Ratings'!D:D, "<"&B39) -> 6.4833333
B39: =EOMONTH(B38, 0) + 1 -> 45689 | C39: =AVERAGEIFS('Pub Ratings'!C:C, 'Pub Ratings'!D:D, ">="&B39, 'Pub Ratings'!D:D, "<"&B40) -> 6.55
B40: =EOMONTH(B39, 0) + 1 -> 45717 | C40: =AVERAGEIFS('Pub Ratings'!C:C, 'Pub Ratings'!D:D, ">="&B40, 'Pub Ratings'!D:D, "<"&B41) -> 6.9
B41: =EOMONTH(B40, 0) + 1 -> 45748 | C41: =AVERAGEIFS('Pub Ratings'!C:C, 'Pub Ratings'!D:D, ">="&B40, 'Pub Ratings'!D:D, "<"&B41) -> 6.9
B42: =EOMONTH(B41, 0) + 1 -> 45778 | C42: =AVERAGEIFS('Pub Ratings'!C:C, 'Pub Ratings'!D:D, ">="&B42, 'Pub Ratings'!D:D, "<"&B43) -> 6.4
B43: =EOMONTH(B42, 0) + 1 -> 45809 | C43: =AVERAGEIFS('Pub Ratings'!C:C, 'Pub Ratings'!D:D, ">="&B43, 'Pub Ratings'!D:D, "<"&B44) -> 6.6
...
